<?xml version="1.0" ?>
<!-- =================================================================================== -->
<!-- |    This document was autogenerated by xacro from /home/kamil/corosect_ws/src/corosect/corosect/iiwa_description/urdf/MRobot.urdf.xacro | -->
<!-- |    EDITING THIS FILE BY HAND IS NOT RECOMMENDED                                 | -->
<!-- =================================================================================== -->
<robot name="m_robot">
    <material name="Black">
        <color rgba="0.0 0.0 0.0 1.0" />
    </material>
    <material name="Blue">
        <color rgba="0.0 0.0 0.8 1.0" />
    </material>
    <material name="Green">
        <color rgba="0.0 0.8 0.0 1.0" />
    </material>
    <material name="Grey">
        <color rgba="0.4 0.4 0.4 1.0" />
    </material>
    <material name="Orange">
        <color rgba="1.0 0.4235294117647059 0.0392156862745098 1.0" />
    </material>
    <material name="Brown">
        <color rgba="0.8705882352941177 0.8117647058823529 0.7647058823529411 1.0" />
    </material>
    <material name="Red">
        <color rgba="0.8 0.0 0.0 1.0" />
    </material>
    <material name="White">
        <color rgba="1.0 1.0 1.0 1.0" />
    </material>
    <material name="Opaque">
        <color rgba="1.0 1.0 1.0 0.8" />
    </material>
    <material name="camera_mat">
        <color rgba="0.25 0.25 0.25 0.99" />
    </material>
    <!--Import the realsense
  <xacro:include filename="$(find realsense2_description)/urdf/_d435.urdf.xacro" /> -->
    <!-- Fix to world just for testing -->
    <link name="base_link" />
    <joint name="artificial_ceiling_to_base" type="fixed">
        <parent link="base_link" />
        <child link="artificial_ceiling" />
        <origin rpy="0 0 0" xyz="0.0 0.0 2.2" />
    </joint>
    <link name="artificial_ceiling">
        <collision>
            <origin rpy="0 0 0" xyz="0 0 0" />
            <geometry>
                <box size="10.0 10.0 0.001" />
            </geometry>
        </collision>
    </link>
     <!--joint between base link and the support structure-->
    <joint name="base_link_m_robot_joint1" type="fixed">
        <origin rpy="0 0 0" xyz="0 0 0" />
        <parent link="base_link" />
        <child link="m_robot_support_structure" />
    </joint>
     <!--support structure definition-->
    <link name="m_robot_support_structure">
        <visual>
            <origin rpy="0 0 3.14159" xyz="0 0 0" />
            <geometry>
                <mesh filename="package://iiwa_description/meshes/Support Structure/Low_Res_Robot_Cell_Nasekomo.stl" />
            </geometry>
            <material name="Grey" />
        </visual>
        <collision>
            <origin rpy="0 0 3.14159" xyz="0 0 0" />
            <geometry>
                <mesh filename="package://iiwa_description/meshes/Support Structure/Low_Res_Robot_Cell_Nasekomo.stl" />
            </geometry>
            <material name="Grey" />
        </collision>
        <inertial>
            <mass value="0.1" />
            <origin xyz="0 0 0" rpy="0 0 0" />
            <inertia ixx="0.03" iyy="0.03" izz="0.03" ixy="0.0" ixz="0.0" iyz="0.0" />
        </inertial>
    </link>
    <!--joint between {parent} and link_0-->
    <joint name="m_robot_support_structure_m_robot_joint" type="fixed">
        <origin rpy="0 0 0" xyz="0 -1.05 0.885" />
        <parent link="m_robot_support_structure" />
        <child link="m_robot_link_0" />
    </joint>
    <link name="m_robot_link_0">
        <inertial>
            <origin rpy="0 0 0" xyz="-0.1 0 0.07" />
            <mass value="5" />
            <inertia ixx="0.05" ixy="0" ixz="0" iyy="0.06" iyz="0" izz="0.03" />
        </inertial>
        <visual>
            <origin rpy="0 0 0" xyz="0 0 0" />
            <geometry>
                <mesh filename="package://iiwa_description/meshes/iiwa14/visual/link_0.stl" />
            </geometry>
            <material name="Grey" />
        </visual>
        <collision>
            <origin rpy="0 0 0" xyz="0 0 0" />
            <geometry>
                <mesh filename="package://iiwa_description/meshes/iiwa14/collision/link_0.stl" />
            </geometry>
            <material name="Grey" />
        </collision>
        <self_collision_checking>
            <origin rpy="0 0 0" xyz="0 0 0" />
            <geometry>
                <capsule length="0.25" radius="0.15" />
            </geometry>
        </self_collision_checking>
    </link>
    <!-- joint between link_0 and link_1 -->
    <joint name="m_robot_joint_1" type="revolute">
        <parent link="m_robot_link_0" />
        <child link="m_robot_link_1" />
        <origin rpy="0 0 0" xyz="0 0 0.1575" />
        <axis xyz="0 0 1" />
        <limit effort="300" lower="-2.9670597283903604" upper="2.9670597283903604" velocity="10" />
        <safety_controller k_position="100" k_velocity="2" soft_lower_limit="-2.9321531433504737" soft_upper_limit="2.9321531433504737" />
        <dynamics damping="0.5" />
    </joint>
    <link name="m_robot_link_1">
        <inertial>
            <origin rpy="0 0 0" xyz="0 -0.03 0.12" />
            <mass value="4" />
            <inertia ixx="0.1" ixy="0" ixz="0" iyy="0.09" iyz="0" izz="0.02" />
        </inertial>
        <visual>
            <origin rpy="0 0 0" xyz="0 0 0" />
            <geometry>
                <mesh filename="package://iiwa_description/meshes/iiwa14/visual/link_1.stl" />
            </geometry>
            <material name="Orange" />
        </visual>
        <collision>
            <origin rpy="0 0 0" xyz="0 0 0" />
            <geometry>
                <mesh filename="package://iiwa_description/meshes/iiwa14/collision/link_1.stl" />
            </geometry>
            <material name="Orange" />
        </collision>
    </link>
    <!-- joint between link_1 and link_2 -->
    <joint name="m_robot_joint_2" type="revolute">
        <parent link="m_robot_link_1" />
        <child link="m_robot_link_2" />
        <origin rpy="1.5707963267948966   0 3.141592653589793" xyz="0 0 0.2025" />
        <axis xyz="0 0 1" />
        <limit effort="300" lower="-2.00713" upper="2.00713" velocity="10" />
        <safety_controller k_position="100" k_velocity="2" soft_lower_limit="-2.0594885173533086" soft_upper_limit="2.0594885173533086" />
        <dynamics damping="0.5" />
    </joint>
    <link name="m_robot_link_2">
        <inertial>
            <origin rpy="0 0 0" xyz="0.0003 0.059 0.042" />
            <mass value="4" />
            <inertia ixx="0.05" ixy="0" ixz="0" iyy="0.018" iyz="0" izz="0.044" />
        </inertial>
        <visual>
            <origin rpy="0 0 0" xyz="0 0 0" />
            <geometry>
                <mesh filename="package://iiwa_description/meshes/iiwa14/visual/link_2.stl" />
            </geometry>
            <material name="Orange" />
        </visual>
        <collision>
            <origin rpy="0 0 0" xyz="0 0 0" />
            <geometry>
                <mesh filename="package://iiwa_description/meshes/iiwa14/collision/link_2.stl" />
            </geometry>
            <material name="Orange" />
        </collision>
    </link>
    <!-- joint between link_2 and link_3 -->
    <joint name="m_robot_joint_3" type="revolute">
        <parent link="m_robot_link_2" />
        <child link="m_robot_link_3" />
        <origin rpy="1.5707963267948966 0 3.141592653589793" xyz="0 0.2045 0" />
        <axis xyz="0 0 1" />
        <limit effort="300" lower="-2.9670597283903604" upper="2.9670597283903604" velocity="10" />
        <safety_controller k_position="100" k_velocity="2" soft_lower_limit="-2.9321531433504737" soft_upper_limit="2.9321531433504737" />
        <dynamics damping="0.5" />
    </joint>
    <link name="m_robot_link_3">
        <inertial>
            <origin rpy="0 0 0" xyz="0 0.03 0.13" />
            <mass value="3" />
            <inertia ixx="0.08" ixy="0" ixz="0" iyy="0.075" iyz="0" izz="0.01" />
        </inertial>
        <visual>
            <origin rpy="0 0 0" xyz="0 0 0" />
            <geometry>
                <mesh filename="package://iiwa_description/meshes/iiwa14/visual/link_3.stl" />
            </geometry>
            <material name="Orange" />
        </visual>
        <collision>
            <origin rpy="0 0 0" xyz="0 0 0" />
            <geometry>
                <mesh filename="package://iiwa_description/meshes/iiwa14/collision/link_3.stl" />
            </geometry>
            <material name="Orange" />
        </collision>
    </link>
    <!-- joint between link_3 and link_4 -->
    <joint name="m_robot_joint_4" type="revolute">
        <parent link="m_robot_link_3" />
        <child link="m_robot_link_4" />
        <origin rpy="1.5707963267948966 0 0" xyz="0 0 0.2155" />
        <axis xyz="0 0 1" />
        <limit effort="300" lower="-2.00713" upper="2.00713" velocity="10" />
        <safety_controller k_position="100" k_velocity="2" soft_lower_limit="-2.0594885173533086" soft_upper_limit="2.0594885173533086" />
        <dynamics damping="0.5" />
    </joint>
    <link name="m_robot_link_4">
        <inertial>
            <origin rpy="0 0 0" xyz="0 0.067 0.034" />
            <mass value="2.7" />
            <inertia ixx="0.03" ixy="0" ixz="0" iyy="0.01" iyz="0" izz="0.029" />
        </inertial>
        <visual>
            <origin rpy="0 0 0" xyz="0 0 0" />
            <geometry>
                <mesh filename="package://iiwa_description/meshes/iiwa14/visual/link_4.stl" />
            </geometry>
            <material name="Orange" />
        </visual>
        <collision>
            <origin rpy="0 0 0" xyz="0 0 0" />
            <geometry>
                <mesh filename="package://iiwa_description/meshes/iiwa14/collision/link_4.stl" />
            </geometry>
            <material name="Orange" />
        </collision>
    </link>
    <!-- joint between link_4 and link_5 -->
    <joint name="m_robot_joint_5" type="revolute">
        <parent link="m_robot_link_4" />
        <child link="m_robot_link_5" />
        <origin rpy="-1.5707963267948966 3.141592653589793 0" xyz="0 0.1845 0" />
        <axis xyz="0 0 1" />
        <limit effort="300" lower="-2.9670597283903604" upper="2.9670597283903604" velocity="10" />
        <safety_controller k_position="100" k_velocity="2" soft_lower_limit="-2.9321531433504737" soft_upper_limit="2.9321531433504737" />
        <dynamics damping="0.5" />
    </joint>
    <link name="m_robot_link_5">
        <inertial>
            <origin rpy="0 0 0" xyz="0.0001 0.021 0.076" />
            <mass value="1.7" />
            <inertia ixx="0.02" ixy="0" ixz="0" iyy="0.018" iyz="0" izz="0.005" />
        </inertial>
        <visual>
            <origin rpy="0 0 0" xyz="0 0 0" />
            <geometry>
                <mesh filename="package://iiwa_description/meshes/iiwa14/visual/link_5.stl" />
            </geometry>
            <material name="Orange" />
        </visual>
        <collision>
            <origin rpy="0 0 0" xyz="0 0 0" />
            <geometry>
                <mesh filename="package://iiwa_description/meshes/iiwa14/collision/link_5.stl" />
            </geometry>
            <material name="Orange" />
        </collision>
    </link>
    <!-- joint between link_5 and link_6 -->
    <joint name="m_robot_joint_6" type="revolute">
        <parent link="m_robot_link_5" />
        <child link="m_robot_link_6" />
        <origin rpy="1.5707963267948966 0 0" xyz="0 0 0.2155" />
        <axis xyz="0 0 1" />
        <limit effort="300" lower="-2.00713" upper="1.91986" velocity="10" />
        <safety_controller k_position="100" k_velocity="2" soft_lower_limit="-2.0094885173533086" soft_upper_limit="2.0094885173533086" />
        <dynamics damping="0.5" />
    </joint>
    <link name="m_robot_link_6">
        <inertial>
            <origin rpy="0 0 0" xyz="0 0.0006 0.0004" />
            <mass value="1.8" />
            <inertia ixx="0.005" ixy="0" ixz="0" iyy="0.0036" iyz="0" izz="0.0047" />
        </inertial>
        <visual>
            <origin rpy="0 0 0" xyz="0 0 0" />
            <geometry>
                <mesh filename="package://iiwa_description/meshes/iiwa14/visual/link_6.stl" />
            </geometry>
            <material name="Orange" />
        </visual>
        <collision>
            <origin rpy="0 0 0" xyz="0 0 0" />
            <geometry>
                <mesh filename="package://iiwa_description/meshes/iiwa14/collision/link_6.stl" />
            </geometry>
            <material name="Orange" />
        </collision>
    </link>
    <!-- joint between link_6 and link_7 -->
    <joint name="m_robot_joint_7" type="revolute">
        <parent link="m_robot_link_6" />
        <child link="m_robot_link_7" />
        <origin rpy="-1.5707963267948966 3.141592653589793 0" xyz="0 0.081 0" />
        <axis xyz="0 0 1" />
        <limit effort="300" lower="-3.0543261909900763" upper="3.0543261909900763" velocity="10" />
        <safety_controller k_position="100" k_velocity="2" soft_lower_limit="-3.01941960595019" soft_upper_limit="3.01941960595019" />
        <dynamics damping="0.5" />
    </joint>
    <link name="m_robot_link_7">
        <inertial>
            <origin rpy="0 0 0" xyz="0 0 0.02" />
            <mass value="0.3" />
            <inertia ixx="0.001" ixy="0" ixz="0" iyy="0.001" iyz="0" izz="0.001" />
        </inertial>
        <visual>
            <origin rpy="0 0 0" xyz="0 0 0" />
            <geometry>
                <mesh filename="package://iiwa_description/meshes/iiwa14/visual/kuka_flange.stl" />
            </geometry>
            <material name="Grey" />
        </visual>
        <collision>
            <origin rpy="0 0 0" xyz="0 0 0" />
            <geometry>
                <mesh filename="package://iiwa_description/meshes/iiwa14/collision/kuka_flange.stl" />
            </geometry>
            <material name="Grey" />
        </collision>
    </link>
    <joint name="m_robot_joint_ee" type="fixed">
        <parent link="m_robot_link_7" />
        <child link="m_robot_link_ee" />
        <origin rpy="0 0 0" xyz="0 0 0.045" />
    </joint>
    <link name="m_robot_link_ee" />
    <!-- Enable the Joint Feedback -->
    <gazebo reference="m_robot_joint_7">
        <provideFeedback>true</provideFeedback>
        <plugin name="gazebo_ros_control">
            <robotNamespace>/</robotNamespace>
        </plugin>
    </gazebo>
    <!-- The ft_sensor plugin -->
    <gazebo>
        <plugin filename="libgazebo_ros_ft_sensor.so" name="ft_sensor">
            <updateRate>50.0</updateRate>
            <topicName>/m_robot/state/CartesianWrench</topicName>
            <jointName>m_robot_joint_7</jointName>
        </plugin>
    </gazebo>
    <!-- Load Gazebo lib and set the robot namespace -->
    <gazebo>
        <plugin filename="libgazebo_ros_control.so" name="gazebo_ros_control">
            <!-- <robotNamespace>/m_robot</robotNamespace> -->
        </plugin>
    </gazebo>
    <!-- Link0 -->
    <gazebo reference="m_robot_link_0">
        <material>Gazebo/Grey</material>
        <mu1>0.2</mu1>
        <mu2>0.2</mu2>
    </gazebo>
    <!-- Link1 -->
    <gazebo reference="m_robot_link_1">
        <material>Gazebo/Orange</material>
        <mu1>0.2</mu1>
        <mu2>0.2</mu2>
    </gazebo>
    <!-- Link2 -->
    <gazebo reference="m_robot_link_2">
        <material>Gazebo/Orange</material>
        <mu1>0.2</mu1>
        <mu2>0.2</mu2>
    </gazebo>
    <!-- Link3 -->
    <gazebo reference="m_robot_link_3">
        <material>Gazebo/Orange</material>
        <mu1>0.2</mu1>
        <mu2>0.2</mu2>
    </gazebo>
    <!-- Link4 -->
    <gazebo reference="m_robot_link_4">
        <material>Gazebo/Orange</material>
        <mu1>0.2</mu1>
        <mu2>0.2</mu2>
    </gazebo>
    <!-- Link5 -->
    <gazebo reference="m_robot_link_5">
        <material>Gazebo/Orange</material>
        <mu1>0.2</mu1>
        <mu2>0.2</mu2>
    </gazebo>
    <!-- Link6 -->
    <gazebo reference="m_robot_link_6">
        <material>Gazebo/Orange</material>
        <mu1>0.2</mu1>
        <mu2>0.2</mu2>
    </gazebo>
    <!-- Link7 -->
    <gazebo reference="m_robot_link_7">
        <material>Gazebo/Grey</material>
        <mu1>0.2</mu1>
        <mu2>0.2</mu2>
    </gazebo>
    <transmission name="m_robot_tran_1">
        <robotNamespace>/m_robot</robotNamespace>
        <type>transmission_interface/SimpleTransmission</type>
        <joint name="m_robot_joint_1">
            <hardwareInterface>hardware_interface/PositionJointInterface</hardwareInterface>
        </joint>
        <actuator name="m_robot_motor_1">
            <hardwareInterface>hardware_interface/PositionJointInterface</hardwareInterface>
            <mechanicalReduction>1</mechanicalReduction>
        </actuator>
    </transmission>
    <transmission name="m_robot_tran_2">
        <robotNamespace>/m_robot</robotNamespace>
        <type>transmission_interface/SimpleTransmission</type>
        <joint name="m_robot_joint_2">
            <hardwareInterface>hardware_interface/PositionJointInterface</hardwareInterface>
        </joint>
        <actuator name="m_robot_motor_2">
            <hardwareInterface>hardware_interface/PositionJointInterface</hardwareInterface>
            <mechanicalReduction>1</mechanicalReduction>
        </actuator>
    </transmission>
    <transmission name="m_robot_tran_3">
        <robotNamespace>/m_robot</robotNamespace>
        <type>transmission_interface/SimpleTransmission</type>
        <joint name="m_robot_joint_3">
            <hardwareInterface>hardware_interface/PositionJointInterface</hardwareInterface>
        </joint>
        <actuator name="m_robot_motor_3">
            <hardwareInterface>hardware_interface/PositionJointInterface</hardwareInterface>
            <mechanicalReduction>1</mechanicalReduction>
        </actuator>
    </transmission>
    <transmission name="m_robot_tran_4">
        <robotNamespace>/m_robot</robotNamespace>
        <type>transmission_interface/SimpleTransmission</type>
        <joint name="m_robot_joint_4">
            <hardwareInterface>hardware_interface/PositionJointInterface</hardwareInterface>
        </joint>
        <actuator name="m_robot_motor_4">
            <hardwareInterface>hardware_interface/PositionJointInterface</hardwareInterface>
            <mechanicalReduction>1</mechanicalReduction>
        </actuator>
    </transmission>
    <transmission name="m_robot_tran_5">
        <robotNamespace>/m_robot</robotNamespace>
        <type>transmission_interface/SimpleTransmission</type>
        <joint name="m_robot_joint_5">
            <hardwareInterface>hardware_interface/PositionJointInterface</hardwareInterface>
        </joint>
        <actuator name="m_robot_motor_5">
            <hardwareInterface>hardware_interface/PositionJointInterface</hardwareInterface>
            <mechanicalReduction>1</mechanicalReduction>
        </actuator>
    </transmission>
    <transmission name="m_robot_tran_6">
        <robotNamespace>/m_robot</robotNamespace>
        <type>transmission_interface/SimpleTransmission</type>
        <joint name="m_robot_joint_6">
            <hardwareInterface>hardware_interface/PositionJointInterface</hardwareInterface>
        </joint>
        <actuator name="m_robot_motor_6">
            <hardwareInterface>hardware_interface/PositionJointInterface</hardwareInterface>
            <mechanicalReduction>1</mechanicalReduction>
        </actuator>
    </transmission>
    <transmission name="m_robot_tran_7">
        <robotNamespace>/m_robot</robotNamespace>
        <type>transmission_interface/SimpleTransmission</type>
        <joint name="m_robot_joint_7">
            <hardwareInterface>hardware_interface/PositionJointInterface</hardwareInterface>
        </joint>
        <actuator name="m_robot_motor_7">
            <hardwareInterface>hardware_interface/PositionJointInterface</hardwareInterface>
            <mechanicalReduction>1</mechanicalReduction>
        </actuator>
    </transmission>
    <joint name="m_robot_link_ee_m_robot_joint_ee" type="fixed">
        <origin rpy="3.14159 0 1.5707963267948966" xyz="0.07 0 0.043" />
        <parent link="m_robot_link_ee" />
        <child link="m_robot_linear_drive_guiderail" />
    </joint>
    <link name="m_robot_linear_drive_guiderail">
        <inertial>
            <origin rpy="0 0 0" xyz="0 0 0" />
            <mass value="0.01" />
            <inertia ixx="0.001" ixy="0" ixz="0" iyy="0.001" iyz="0" izz="0.001" />
        </inertial>
        <visual>
            <origin rpy="0 0 0" xyz="0 0 0" />
            <geometry>
                <mesh filename="package://iiwa_description/meshes/Linear Drive Sept2023/Guide Rail.stl" />
            </geometry>
            <material name="Grey" />
        </visual>
        <collision>d
            <origin rpy="0 0 0" xyz="0 0 0" />
            <geometry>
                <mesh filename="package://iiwa_description/meshes/Linear Drive Sept2023/Guide Rail.stl" />
            </geometry>
            <material name="Grey" />
        </collision>
    </link>
    <joint name="m_robot_linear_drive_guiderail_sledge_joint" type="prismatic">
        <origin rpy="0 0 3.14159" xyz="0 -0.12 -0.022" />
        <parent link="m_robot_linear_drive_guiderail" />
        <child link="m_robot_linear_drive_sledge" />
        <limit effort="1" lower="0.0" upper="0.33" velocity="0.3" />
        <axis xyz="0 1 0" />
    </joint>
    <link name="m_robot_linear_drive_sledge">
        <inertial>
            <origin rpy="0 0 0" xyz="0 0 0" />
            <mass value="0.01" />
            <inertia ixx="0.001" ixy="0" ixz="0" iyy="0.001" iyz="0" izz="0.001" />
        </inertial>
        <visual>
            <origin rpy="0 0 0" xyz="0 0 0" />
            <geometry>
                <mesh filename="package://iiwa_description/meshes/Linear Drive Sept2023/Sledge Assembly.stl" />
            </geometry>
            <material name="Orange" />
        </visual>
        <collision>
            <origin rpy="0 0 0" xyz="0 0 0" />
            <geometry>
                <mesh filename="package://iiwa_description/meshes/Linear Drive Sept2023/Sledge Assembly.stl" />
            </geometry>
        </collision>
    </link>
    <joint name="m_robot_linear_drive_sledge_dof1_joint" type="revolute">
        <origin rpy="0 0 0" xyz="0 0 -0.015" />
        <parent link="m_robot_linear_drive_sledge" />
        <child link="m_robot_linear_drive_dof1" />
        <axis xyz="0 0 1" />
        <limit effort="1" lower="-1.571" upper="1.571" velocity="0.95" />
    </joint>
    <link name="m_robot_linear_drive_dof1">
        <inertial>
            <origin rpy="0 0 0" xyz="0 0 0" />
            <mass value="0.01" />
            <inertia ixx="0.001" ixy="0" ixz="0" iyy="0.001" iyz="0" izz="0.001" />
        </inertial>
        <visual>
            <origin rpy="0 0 0" xyz="0 0 0" />
            <geometry>
                <mesh filename="package://iiwa_description/meshes/Linear Drive Sept2023/2 DOF.stl" />
            </geometry>
            <material name="Grey" />
        </visual>
        <collision>
            <origin rpy="0 0 0" xyz="0 0 0" />
            <geometry>
                <mesh filename="package://iiwa_description/meshes/Linear Drive Sept2023/2 DOF.stl" />
            </geometry>
            <material name="Grey" />
        </collision>
    </link>
    <joint name="m_robot_linear_drive_dof1_dof2_joint" type="revolute">
        <origin rpy="0 0 0" xyz="0 0 -0.071" />
        <parent link="m_robot_linear_drive_dof1" />
        <child link="m_robot_linear_drive_dof2" />
        <axis xyz="1 0 0" />
        <limit effort="1" lower="-1.571" upper="0.0" velocity="0.95" />
    </joint>
    <link name="m_robot_linear_drive_dof2">
        <inertial>
            <origin rpy="0 0 0" xyz="0 0 0" />
            <mass value="0.01" />
            <inertia ixx="0.001" ixy="0" ixz="0" iyy="0.001" iyz="0" izz="0.001" />
        </inertial>
        <visual>
            <origin rpy="0 0 0" xyz="0 0 0" />
            <geometry>
                <mesh filename="package://iiwa_description/meshes/Linear Drive Sept2023/3DOF.stl" />
            </geometry>
            <material name="Grey" />
        </visual>
        <collision>
            <origin rpy="0 0 0" xyz="0 0 0" />
            <geometry>
                <mesh filename="package://iiwa_description/meshes/Linear Drive Sept2023/3DOF.stl" />
            </geometry>
            <material name="Grey" />
        </collision>
    </link>
    <joint name="m_robot_linear_drive_joint_ee" type="fixed">
        <parent link="m_robot_linear_drive_dof2" />
        <child link="m_robot_linear_drive_link_ee" />
        <origin rpy="0 0 0" xyz="0 0.32 -0.0625" />
    </joint>
    <link name="m_robot_linear_drive_link_ee">
        <visual>
            <origin rpy="0 0 0" xyz="0 0 0" />
            <geometry>
                <box size="0.01 0.01 0.01" />
            </geometry>
            <material name="Grey" />
        </visual>
    </link>

    <transmission name="m_robot_linear_drive_guiderail_sledge_tran">
        <robotNamespace>/m_robot</robotNamespace>
        <type>transmission_interface/SimpleTransmission</type>
        <joint name="m_robot_linear_drive_guiderail_sledge_joint">
            <hardwareInterface>hardware_interface/PositionJointInterface</hardwareInterface>
        </joint>
        <actuator name="m_robot_linear_drive_guiderail_sledge_motor">
            <hardwareInterface>hardware_interface/PositionJointInterface</hardwareInterface>
            <mechanicalReduction>1</mechanicalReduction>
        </actuator>
    </transmission>
    <transmission name="m_robot_linear_drive_sledge_dof1_tran">
        <robotNamespace>/m_robot</robotNamespace>
        <type>transmission_interface/SimpleTransmission</type>
        <joint name="m_robot_linear_drive_sledge_dof1_joint">
            <hardwareInterface>hardware_interface/PositionJointInterface</hardwareInterface>
        </joint>
        <actuator name="m_robot_linear_drive_sledge_dof1_motor">
            <hardwareInterface>hardware_interface/PositionJointInterface</hardwareInterface>
            <mechanicalReduction>1</mechanicalReduction>
        </actuator>
    </transmission>
    <transmission name="m_robot_linear_drive_dof1_dof2_tran">
        <robotNamespace>/m_robot</robotNamespace>
        <type>transmission_interface/SimpleTransmission</type>
        <joint name="m_robot_linear_drive_dof1_dof2_joint">
            <hardwareInterface>hardware_interface/PositionJointInterface</hardwareInterface>
        </joint>
        <actuator name="m_robot_linear_drive_dof1_dof2_motor">
            <hardwareInterface>hardware_interface/PositionJointInterface</hardwareInterface>
            <mechanicalReduction>1</mechanicalReduction>
        </actuator>
    </transmission>
    <!--joint between {parent} and link_0-->
    <joint name="m_robot_linear_drive_link_ee_Soft_RG6_joint" type="fixed">
        <origin rpy="3.14159 1.571 -1.571" xyz="0 -0.385 0" />
        <parent link="m_robot_linear_drive_link_ee" />
        <child link="Soft_RG6_link_0" />
    </joint>
    <link name="Soft_RG6_link_0">
        <inertial>
            <origin rpy="0 0 0" xyz="0 0 0" />
            <mass value="0.1" />
            <inertia ixx="0.001" ixy="0" ixz="0" iyy="0.009" iyz="0" izz="0.002" />
        </inertial>
        <visual>
            <origin rpy="0 0 0" xyz="0 0 0" />
            <geometry>
                <mesh filename="package://iiwa_description/meshes/OnRobot/rg6_body_low_res.stl" />
            </geometry>
            <material name="Grey" />
        </visual>
        <collision>
            <origin rpy="0 0 0" xyz="0 0 0" />
            <geometry>
                <mesh filename="package://iiwa_description/meshes/OnRobot/rg6_body_low_res.stl" />
            </geometry>
        </collision>
    </link>
    <!-- joint between link_0 and arm_1 -->
    <joint name="Soft_RG6_joint_1_1" type="revolute">
        <parent link="Soft_RG6_link_0" />
        <child link="Soft_RG6_arm_1" />
        <origin rpy="0 0 0" xyz="0.0 -0.035 0.13" />
        <axis xyz="1 0 0" />
        <limit effort="1" lower="0.95" upper="2.2" velocity="10" />
        <dynamics damping="0.1" />
    </joint>
    <link name="Soft_RG6_arm_1">
        <inertial>
            <origin rpy="0 0 0" xyz="0 0.0 0.0" />
            <mass value="0.01" />
            <inertia ixx="0.001" ixy="0" ixz="0" iyy="0.001" iyz="0" izz="0.001" />
        </inertial>
        <visual>
            <origin rpy="0 0 0" xyz="0 0.0 0.0" />
            <geometry>
                <mesh filename="package://iiwa_description/meshes/OnRobot/rg6_arm_low_res.stl" />
            </geometry>
            <material name="Orange" />
        </visual>
        <collision>
            <origin rpy="0 0 0" xyz="0 0.0 0.0" />
            <geometry>
                <mesh filename="package://iiwa_description/meshes/OnRobot/rg6_arm_low_res.stl" />
            </geometry>
        </collision>
    </link>
    <!-- joint between arm_1 and finger_1 -->
    <joint name="Soft_RG6_joint_1_2" type="revolute">
        <parent link="Soft_RG6_arm_1" />
        <child link="Soft_RG6_finger_1" />
        <origin rpy="-1.571 3.141592653589793 0" xyz="-0.002 0.065 0.045" />
        <axis xyz="1 0 0" />
        <limit effort="1" lower="-0.62" upper="0.67" velocity="10" />
        <dynamics damping="0.1" />
    </joint>
    <link name="Soft_RG6_finger_1">
        <inertial>
            <origin rpy="0 0 0" xyz="0 0.0 0.0" />
            <mass value="0.01" />
            <inertia ixx="0.001" ixy="0" ixz="0" iyy="0.001" iyz="0" izz="0.001" />
        </inertial>
        <visual>
            <origin rpy="0 0 0" xyz="0 0.0 0.0" />
            <geometry>
                <mesh filename="package://iiwa_description/meshes/End Effector Designs/soft_gripper_rg6_finger_LARGE.stl" />
            </geometry>
            <material name="Grey" />
        </visual>
        <collision>
            <origin rpy="0 0 0" xyz="0 0.0 0.0" />
            <geometry>
                <mesh filename="package://iiwa_description/meshes/End Effector Designs/soft_gripper_rg6_finger_LARGE.stl" />
            </geometry>
        </collision>
    </link>
    <!-- joint between link_0 and arm_2 -->
    <joint name="Soft_RG6_joint_2_1" type="revolute">
        <parent link="Soft_RG6_link_0" />
        <child link="Soft_RG6_arm_2" />
        <origin rpy="0 0 -3.14159" xyz="0.0 0.035 0.13" />
        <axis xyz="1 0 0" />
        <limit effort="1" lower="0.95" upper="2.2" velocity="10" />
        <dynamics damping="0.1" />
    </joint>
    <link name="Soft_RG6_arm_2">
        <inertial>
            <origin rpy="0 0 0" xyz="0 0 0.0" />
            <mass value="0.01" />
            <inertia ixx="0.001" ixy="0" ixz="0" iyy="0.001" iyz="0" izz="0.001" />
        </inertial>
        <visual>
            <origin rpy="0 0 0" xyz="0 0 0.0" />
            <geometry>
                <mesh filename="package://iiwa_description/meshes/OnRobot/rg6_arm_low_res.stl" />
            </geometry>
            <material name="Orange" />
        </visual>
        <collision>
            <origin rpy="0 0 0" xyz="0 0 0.0" />
            <geometry>
                <mesh filename="package://iiwa_description/meshes/OnRobot/rg6_arm_low_res.stl" />
            </geometry>
        </collision>
    </link>
    <!-- joint between arm_2 and finger_2 -->
    <joint name="Soft_RG6_joint_2_2" type="revolute">
        <parent link="Soft_RG6_arm_2" />
        <child link="Soft_RG6_finger_2" />
        <origin rpy="-1.571 3.141592653589793 0" xyz="-0.002 0.065 0.045" />
        <axis xyz="1 0 0" />
        <limit effort="1" lower="-0.62" upper="0.67" velocity="10" />
        <dynamics damping="0.1" />
    </joint>
    <link name="Soft_RG6_finger_2">
        <inertial>
            <origin rpy="0 0 0" xyz="0 0.0 0.0" />
            <mass value="0.01" />
            <inertia ixx="0.001" ixy="0" ixz="0" iyy="0.001" iyz="0" izz="0.001" />
        </inertial>
        <visual>
            <origin rpy="0 0 0" xyz="0 0.0 0.0" />
            <geometry>
                <mesh filename="package://iiwa_description/meshes/End Effector Designs/soft_gripper_rg6_finger_LARGE.stl" />
            </geometry>
            <material name="Grey" />
        </visual>
        <collision>
            <origin rpy="0 0 0" xyz="0 0.0 0.0" />
            <geometry>
                <mesh filename="package://iiwa_description/meshes/End Effector Designs/soft_gripper_rg6_finger_LARGE.stl" />
            </geometry>
        </collision>
    </link>
    <transmission name="Soft_RG6_tran_1_1">
        <robotNamespace>/m_robot</robotNamespace>
        <type>transmission_interface/SimpleTransmission</type>
        <joint name="Soft_RG6_joint_1_1">
            <hardwareInterface>hardware_interface/PositionJointInterface</hardwareInterface>
        </joint>
        <actuator name="Soft_RG6_motor_1_1">
            <hardwareInterface>hardware_interface/PositionJointInterface</hardwareInterface>
            <mechanicalReduction>1</mechanicalReduction>
        </actuator>
    </transmission>
    <transmission name="Soft_RG6_tran_1_2">
        <robotNamespace>/m_robot</robotNamespace>
        <type>transmission_interface/SimpleTransmission</type>
        <joint name="Soft_RG6_joint_1_2">
            <hardwareInterface>hardware_interface/PositionJointInterface</hardwareInterface>
        </joint>
        <actuator name="Soft_RG6_motor_1_2">
            <hardwareInterface>hardware_interface/PositionJointInterface</hardwareInterface>
            <mechanicalReduction>1</mechanicalReduction>
        </actuator>
    </transmission>
    <transmission name="Soft_RG6_tran_2_1">
        <robotNamespace>m_robot</robotNamespace>
        <type>transmission_interface/SimpleTransmission</type>
        <joint name="Soft_RG6_joint_2_1">
            <hardwareInterface>hardware_interface/PositionJointInterface</hardwareInterface>
        </joint>
        <actuator name="Soft_RG6_motor_2_1">
            <hardwareInterface>hardware_interface/PositionJointInterface</hardwareInterface>
            <mechanicalReduction>1</mechanicalReduction>
        </actuator>
    </transmission>
    <transmission name="Soft_RG6_tran_2_2">
        <robotNamespace>/m_robot</robotNamespace>
        <type>transmission_interface/SimpleTransmission</type>
        <joint name="Soft_RG6_joint_2_2">
            <hardwareInterface>hardware_interface/PositionJointInterface</hardwareInterface>
        </joint>
        <actuator name="Soft_RG6_motor_2_2">
            <hardwareInterface>hardware_interface/PositionJointInterface</hardwareInterface>
            <mechanicalReduction>1</mechanicalReduction>
        </actuator>
    </transmission>
    <!-- d435
  <xacro:sensor_d435 parent="$(arg ee_name)_link_0" use_nominal_extrinsics="$(arg use_nominal_extrinsics)" add_plug="$(arg add_plug)" use_mesh="$(arg use_mesh)">
    <origin xyz="$(arg realsense_origin_xyz)" rpy="$(arg realsense_origin_rpy)"/>
  </xacro:sensor_d435>-->
    <!-- Camera mounting point (the threaded screw hole in the bottom) -->

    <link name="realsense_base_link" >
        <visual>
            <geometry>
                <mesh filename="package://iiwa_description/meshes/RealSense D435/d435.dae" />
            </geometry>
            <material name="camera_mat" />
        </visual>
        <collision>
            <geometry>
                <mesh filename="package://iiwa_description/meshes/RealSense D435/d435.dae" />
            </geometry>
        </collision>
        <inertial>
            <mass value="0.1" />
            <origin xyz="0 0 0" rpy="0 0 0" />
            <inertia ixx="0.03" iyy="0.03" izz="0.03" ixy="0.0" ixz="0.0" iyz="0.0" />
        </inertial>
    </link>
    <joint name="realsense_base_joint" type="fixed">
        <parent link="Soft_RG6_finger_2" />
        <child link="realsense_base_link" />
        <origin rpy="0 0 -1.57" xyz="0 0.05 0.1" />
    </joint>
</robot>
