<?xml version="1.0" ?>
<!-- =================================================================================== -->
<!-- |    This document was autogenerated by xacro from /home/kamil/corosect_ws/src/corosect/corosect/iiwa_description/urdf/MRobot.urdf.xacro | -->
<!-- |    EDITING THIS FILE BY HAND IS NOT RECOMMENDED                                 | -->
<!-- =================================================================================== -->
<robot name="m_robot">
    <material name="Black">
        <color rgba="0.0 0.0 0.0 1.0" />
    </material>
    <material name="Blue">
        <color rgba="0.0 0.0 0.8 1.0" />
    </material>
    <material name="Green">
        <color rgba="0.0 0.8 0.0 1.0" />
    </material>
    <material name="Grey">
        <color rgba="0.4 0.4 0.4 1.0" />
    </material>
    <material name="Orange">
        <color rgba="1.0 0.4235294117647059 0.0392156862745098 1.0" />
    </material>
    <material name="Brown">
        <color rgba="0.8705882352941177 0.8117647058823529 0.7647058823529411 1.0" />
    </material>
    <material name="Red">
        <color rgba="0.8 0.0 0.0 1.0" />
    </material>
    <material name="White">
        <color rgba="1.0 1.0 1.0 1.0" />
    </material>
    <material name="zed_mat">
        <color rgba="0.8 0.8 0.8 0.8" />
    </material>
    <material name="zedm_mat">
        <color rgba="0 0 0 0.9" />
    </material>
    <material name="zed2_mat">
        <color rgba="0.25 0.25 0.25 0.99" />
    </material>
    <material name="zed2i_mat">
        <color rgba="0.25 0.25 0.25 0.99" />
    </material>
    <!-- Fix to world just for testing -->
    <link name="base_link" />
    <!--joint between {parent} and link_0-->
    <joint name="m_robot_support_structure_m_robot_joint" type="fixed">
        <origin rpy="0 0 1.5707963267948966" xyz="0 -0.05 0.75" />
        <parent link="base_link" />
        <child link="m_robot_link_0" />
    </joint>
    <link name="m_robot_link_0">
        <inertial>
            <origin rpy="0 0 0" xyz="-0.1 0 0.07" />
            <mass value="5" />
            <inertia ixx="0.05" ixy="0" ixz="0" iyy="0.06" iyz="0" izz="0.03" />
        </inertial>
        <visual>
            <origin rpy="0 0 0" xyz="0 0 0" />
            <geometry>
                <mesh filename="package://iiwa_description/meshes/iiwa14/visual/link_0.stl" />
            </geometry>
            <material name="Grey" />
        </visual>
        <collision>
            <origin rpy="0 0 0" xyz="0 0 0" />
            <geometry>
                <mesh filename="package://iiwa_description/meshes/iiwa14/collision/link_0.stl" />
            </geometry>
            <material name="Grey" />
        </collision>
        <self_collision_checking>
            <origin rpy="0 0 0" xyz="0 0 0" />
            <geometry>
                <capsule length="0.25" radius="0.15" />
            </geometry>
        </self_collision_checking>
    </link>
    <!-- joint between link_0 and link_1 -->
    <joint name="m_robot_joint_1" type="revolute">
        <parent link="m_robot_link_0" />
        <child link="m_robot_link_1" />
        <origin rpy="0 0 0" xyz="0 0 0.1575" />
        <axis xyz="0 0 1" />
        <limit effort="300" lower="-2.9670597283903604" upper="2.9670597283903604" velocity="10" />
        <safety_controller k_position="100" k_velocity="2" soft_lower_limit="-2.9321531433504737" soft_upper_limit="2.9321531433504737" />
        <dynamics damping="0.5" />
    </joint>
    <link name="m_robot_link_1">
        <inertial>
            <origin rpy="0 0 0" xyz="0 -0.03 0.12" />
            <mass value="4" />
            <inertia ixx="0.1" ixy="0" ixz="0" iyy="0.09" iyz="0" izz="0.02" />
        </inertial>
        <visual>
            <origin rpy="0 0 0" xyz="0 0 0" />
            <geometry>
                <mesh filename="package://iiwa_description/meshes/iiwa14/visual/link_1.stl" />
            </geometry>
            <material name="Orange" />
        </visual>
        <collision>
            <origin rpy="0 0 0" xyz="0 0 0" />
            <geometry>
                <mesh filename="package://iiwa_description/meshes/iiwa14/collision/link_1.stl" />
            </geometry>
            <material name="Orange" />
        </collision>
    </link>
    <!-- joint between link_1 and link_2 -->
    <joint name="m_robot_joint_2" type="revolute">
        <parent link="m_robot_link_1" />
        <child link="m_robot_link_2" />
        <origin rpy="1.5707963267948966   0 3.141592653589793" xyz="0 0 0.2025" />
        <axis xyz="0 0 1" />
        <limit effort="300" lower="-2.0943951023931953" upper="2.0943951023931953" velocity="10" />
        <safety_controller k_position="100" k_velocity="2" soft_lower_limit="-2.0594885173533086" soft_upper_limit="2.0594885173533086" />
        <dynamics damping="0.5" />
    </joint>
    <link name="m_robot_link_2">
        <inertial>
            <origin rpy="0 0 0" xyz="0.0003 0.059 0.042" />
            <mass value="4" />
            <inertia ixx="0.05" ixy="0" ixz="0" iyy="0.018" iyz="0" izz="0.044" />
        </inertial>
        <visual>
            <origin rpy="0 0 0" xyz="0 0 0" />
            <geometry>
                <mesh filename="package://iiwa_description/meshes/iiwa14/visual/link_2.stl" />
            </geometry>
            <material name="Orange" />
        </visual>
        <collision>
            <origin rpy="0 0 0" xyz="0 0 0" />
            <geometry>
                <mesh filename="package://iiwa_description/meshes/iiwa14/collision/link_2.stl" />
            </geometry>
            <material name="Orange" />
        </collision>
    </link>
    <!-- joint between link_2 and link_3 -->
    <joint name="m_robot_joint_3" type="revolute">
        <parent link="m_robot_link_2" />
        <child link="m_robot_link_3" />
        <origin rpy="1.5707963267948966 0 3.141592653589793" xyz="0 0.2045 0" />
        <axis xyz="0 0 1" />
        <limit effort="300" lower="-2.9670597283903604" upper="2.9670597283903604" velocity="10" />
        <safety_controller k_position="100" k_velocity="2" soft_lower_limit="-2.9321531433504737" soft_upper_limit="2.9321531433504737" />
        <dynamics damping="0.5" />
    </joint>
    <link name="m_robot_link_3">
        <inertial>
            <origin rpy="0 0 0" xyz="0 0.03 0.13" />
            <mass value="3" />
            <inertia ixx="0.08" ixy="0" ixz="0" iyy="0.075" iyz="0" izz="0.01" />
        </inertial>
        <visual>
            <origin rpy="0 0 0" xyz="0 0 0" />
            <geometry>
                <mesh filename="package://iiwa_description/meshes/iiwa14/visual/link_3.stl" />
            </geometry>
            <material name="Orange" />
        </visual>
        <collision>
            <origin rpy="0 0 0" xyz="0 0 0" />
            <geometry>
                <mesh filename="package://iiwa_description/meshes/iiwa14/collision/link_3.stl" />
            </geometry>
            <material name="Orange" />
        </collision>
    </link>
    <!-- joint between link_3 and link_4 -->
    <joint name="m_robot_joint_4" type="revolute">
        <parent link="m_robot_link_3" />
        <child link="m_robot_link_4" />
        <origin rpy="1.5707963267948966 0 0" xyz="0 0 0.2155" />
        <axis xyz="0 0 1" />
        <limit effort="300" lower="-2.0943951023931953" upper="2.0943951023931953" velocity="10" />
        <safety_controller k_position="100" k_velocity="2" soft_lower_limit="-2.0594885173533086" soft_upper_limit="2.0594885173533086" />
        <dynamics damping="0.5" />
    </joint>
    <link name="m_robot_link_4">
        <inertial>
            <origin rpy="0 0 0" xyz="0 0.067 0.034" />
            <mass value="2.7" />
            <inertia ixx="0.03" ixy="0" ixz="0" iyy="0.01" iyz="0" izz="0.029" />
        </inertial>
        <visual>
            <origin rpy="0 0 0" xyz="0 0 0" />
            <geometry>
                <mesh filename="package://iiwa_description/meshes/iiwa14/visual/link_4.stl" />
            </geometry>
            <material name="Orange" />
        </visual>
        <collision>
            <origin rpy="0 0 0" xyz="0 0 0" />
            <geometry>
                <mesh filename="package://iiwa_description/meshes/iiwa14/collision/link_4.stl" />
            </geometry>
            <material name="Orange" />
        </collision>
    </link>
    <!-- joint between link_4 and link_5 -->
    <joint name="m_robot_joint_5" type="revolute">
        <parent link="m_robot_link_4" />
        <child link="m_robot_link_5" />
        <origin rpy="-1.5707963267948966 3.141592653589793 0" xyz="0 0.1845 0" />
        <axis xyz="0 0 1" />
        <limit effort="300" lower="-2.9670597283903604" upper="2.9670597283903604" velocity="10" />
        <safety_controller k_position="100" k_velocity="2" soft_lower_limit="-2.9321531433504737" soft_upper_limit="2.9321531433504737" />
        <dynamics damping="0.5" />
    </joint>
    <link name="m_robot_link_5">
        <inertial>
            <origin rpy="0 0 0" xyz="0.0001 0.021 0.076" />
            <mass value="1.7" />
            <inertia ixx="0.02" ixy="0" ixz="0" iyy="0.018" iyz="0" izz="0.005" />
        </inertial>
        <visual>
            <origin rpy="0 0 0" xyz="0 0 0" />
            <geometry>
                <mesh filename="package://iiwa_description/meshes/iiwa14/visual/link_5.stl" />
            </geometry>
            <material name="Orange" />
        </visual>
        <collision>
            <origin rpy="0 0 0" xyz="0 0 0" />
            <geometry>
                <mesh filename="package://iiwa_description/meshes/iiwa14/collision/link_5.stl" />
            </geometry>
            <material name="Orange" />
        </collision>
    </link>
    <!-- joint between link_5 and link_6 -->
    <joint name="m_robot_joint_6" type="revolute">
        <parent link="m_robot_link_5" />
        <child link="m_robot_link_6" />
        <origin rpy="1.5707963267948966 0 0" xyz="0 0 0.2155" />
        <axis xyz="0 0 1" />
        <limit effort="300" lower="-2.0943951023931953" upper="2.0943951023931953" velocity="10" />
        <safety_controller k_position="100" k_velocity="2" soft_lower_limit="-2.0594885173533086" soft_upper_limit="2.0594885173533086" />
        <dynamics damping="0.5" />
    </joint>
    <link name="m_robot_link_6">
        <inertial>
            <origin rpy="0 0 0" xyz="0 0.0006 0.0004" />
            <mass value="1.8" />
            <inertia ixx="0.005" ixy="0" ixz="0" iyy="0.0036" iyz="0" izz="0.0047" />
        </inertial>
        <visual>
            <origin rpy="0 0 0" xyz="0 0 0" />
            <geometry>
                <mesh filename="package://iiwa_description/meshes/iiwa14/visual/link_6.stl" />
            </geometry>
            <material name="Orange" />
        </visual>
        <collision>
            <origin rpy="0 0 0" xyz="0 0 0" />
            <geometry>
                <mesh filename="package://iiwa_description/meshes/iiwa14/collision/link_6.stl" />
            </geometry>
            <material name="Orange" />
        </collision>
    </link>
    <!-- joint between link_6 and link_7 -->
    <joint name="m_robot_joint_7" type="revolute">
        <parent link="m_robot_link_6" />
        <child link="m_robot_link_7" />
        <origin rpy="-1.5707963267948966 3.141592653589793 0" xyz="0 0.081 0" />
        <axis xyz="0 0 1" />
        <limit effort="300" lower="-3.0543261909900763" upper="3.0543261909900763" velocity="10" />
        <safety_controller k_position="100" k_velocity="2" soft_lower_limit="-3.01941960595019" soft_upper_limit="3.01941960595019" />
        <dynamics damping="0.5" />
    </joint>
    <link name="m_robot_link_7">
        <inertial>
            <origin rpy="0 0 0" xyz="0 0 0.02" />
            <mass value="0.3" />
            <inertia ixx="0.001" ixy="0" ixz="0" iyy="0.001" iyz="0" izz="0.001" />
        </inertial>
        <visual>
            <origin rpy="0 0 0" xyz="0 0 0" />
            <geometry>
                <mesh filename="package://iiwa_description/meshes/iiwa14/visual/kuka_flange.stl" />
            </geometry>
            <material name="Grey" />
        </visual>
        <collision>
            <origin rpy="0 0 0" xyz="0 0 0" />
            <geometry>
                <mesh filename="package://iiwa_description/meshes/iiwa14/collision/kuka_flange.stl" />
            </geometry>
            <material name="Grey" />
        </collision>
    </link>
    <joint name="m_robot_joint_ee" type="fixed">
        <parent link="m_robot_link_7" />
        <child link="m_robot_link_ee" />
        <origin rpy="0 0 0" xyz="0 0 0.045" />
    </joint>
    <link name="m_robot_link_ee" />
    <joint name="m_robot_link_ee_m_robot_joint_ee" type="fixed">
        <origin rpy="0 0 1.5707963267948966" xyz="0.08 0 0.08" />
        <parent link="m_robot_link_ee" />
        <child link="m_robot_linear_drive_guiderail" />
    </joint>
    <link name="m_robot_linear_drive_guiderail">
        <inertial>
            <origin rpy="0 0 0" xyz="0 0 0" />
            <mass value="0.01" />
            <inertia ixx="0.001" ixy="0" ixz="0" iyy="0.001" iyz="0" izz="0.001" />
        </inertial>
        <visual>
            <origin rpy="0 0 0" xyz="0 0 0" />
            <geometry>
                <mesh filename="package://iiwa_description/meshes/lower_quality_linear_drive/Guide_Rail_v63_true_scale.stl" />
            </geometry>
            <material name="Grey" />
        </visual>
        <collision>
            <origin rpy="0 0 0" xyz="0 0 0" />
            <geometry>
                <mesh filename="package://iiwa_description/meshes/lower_quality_linear_drive/Guide_Rail_v63_true_scale.stl" />
            </geometry>
            <material name="Grey" />
        </collision>
    </link>
    <joint name="m_robot_linear_drive_guiderail_sledge_joint" type="prismatic">
        <origin rpy="0 0 0" xyz="0 0 0.0413" />
        <parent link="m_robot_linear_drive_guiderail" />
        <child link="m_robot_linear_drive_sledge" />
        <limit effort="1" lower="0.0795" upper="0.4205" velocity="0.95" />
        <axis xyz="0 1 0" />
    </joint>
    <link name="m_robot_linear_drive_sledge">
        <inertial>
            <origin rpy="0 0 0" xyz="0 0 0" />
            <mass value="0.01" />
            <inertia ixx="0.001" ixy="0" ixz="0" iyy="0.001" iyz="0" izz="0.001" />
        </inertial>
        <visual>
            <origin rpy="0 0 0" xyz="0 0 0" />
            <geometry>
                <mesh filename="package://iiwa_description/meshes/lower_quality_linear_drive/Sledge_v56_true_scale.stl" />
            </geometry>
            <material name="Grey" />
        </visual>
        <collision>
            <origin rpy="0 0 0" xyz="0 0 0" />
            <geometry>
                <mesh filename="package://iiwa_description/meshes/lower_quality_linear_drive/Sledge_v56_true_scale.stl" />
            </geometry>
            <material name="Grey" />
        </collision>
    </link>
    <joint name="m_robot_linear_drive_sledge_dof1_joint" type="revolute">
        <origin rpy="0 0 0" xyz="0 0 0" />
        <parent link="m_robot_linear_drive_sledge" />
        <child link="m_robot_linear_drive_dof1" />
        <axis xyz="0 0 1" />
        <limit effort="1" lower="-1.571" upper="1.571" velocity="0.95" />
    </joint>
    <link name="m_robot_linear_drive_dof1">
        <inertial>
            <origin rpy="0 0 0" xyz="-0.09 -0.003 0.055" />
            <mass value="0.01" />
            <inertia ixx="0.001" ixy="0" ixz="0" iyy="0.001" iyz="0" izz="0.001" />
        </inertial>
        <visual>
            <origin rpy="0 0 0" xyz="-0.09 -0.003 0.055" />
            <geometry>
                <mesh filename="package://iiwa_description/meshes/lower_quality_linear_drive/2_DOF_v85_true_scale.stl" />
            </geometry>
            <material name="Grey" />
        </visual>
        <collision>
            <origin rpy="0 0 0" xyz="-0.09 -0.003 0.055" />
            <geometry>
                <mesh filename="package://iiwa_description/meshes/lower_quality_linear_drive/2_DOF_v85_true_scale.stl" />
            </geometry>
            <material name="Grey" />
        </collision>
    </link>
    <joint name="m_robot_linear_drive_dof1_dof2_joint" type="revolute">
        <origin rpy="0 0 0" xyz="-0.02 0.005 0.074" />
        <parent link="m_robot_linear_drive_dof1" />
        <child link="m_robot_linear_drive_dof2" />
        <axis xyz="1 0 0" />
        <limit effort="1" lower="-1.5707963267948966" upper="0" velocity="0.95" />
    </joint>
    <link name="m_robot_linear_drive_dof2">
        <inertial>
            <origin rpy="0 0 -1.5707963267948966" xyz="0 0.01 0.005" />
            <mass value="0.01" />
            <inertia ixx="0.001" ixy="0" ixz="0" iyy="0.001" iyz="0" izz="0.001" />
        </inertial>
        <visual>
            <origin rpy="0 0 -1.5707963267948966" xyz="0 0.01 0.005" />
            <geometry>
                <mesh filename="package://iiwa_description/meshes/lower_quality_linear_drive/3_DOF_v36_true_scale.stl" />
            </geometry>
            <material name="Grey" />
        </visual>
        <collision>
            <origin rpy="0 0 -1.5707963267948966" xyz="0 0.01 0.005" />
            <geometry>
                <mesh filename="package://iiwa_description/meshes/lower_quality_linear_drive/3_DOF_v36_true_scale.stl" />
            </geometry>
            <material name="Grey" />
        </collision>
    </link>
    <joint name="m_robot_linear_drive_joint_ee" type="fixed">
        <parent link="m_robot_linear_drive_dof2" />
        <child link="m_robot_linear_drive_link_ee" />
        <origin rpy="0 0 0" xyz="0 0 0" />
    </joint>
    <link name="m_robot_linear_drive_link_ee" />
    <!--joint between {parent} and link_0-->
    <joint name="m_robot_linear_drive_link_ee_Soft_RG6_joint" type="fixed">
        <origin rpy="0 0 -1.571" xyz="0.0165 0 0.04" />
        <parent link="m_robot_linear_drive_link_ee" />
        <child link="Soft_RG6_link_0" />
    </joint>
    <link name="Soft_RG6_link_0">
        <inertial>
            <origin rpy="0 0 0" xyz="0 0 0" />
            <mass value="0.1" />
            <inertia ixx="0.001" ixy="0" ixz="0" iyy="0.009" iyz="0" izz="0.002" />
        </inertial>
        <visual>
            <origin rpy="0 0 0" xyz="0 0 0" />
            <geometry>
                <mesh filename="package://iiwa_description/meshes/OnRobot/rg6_body.stl" />
            </geometry>
            <material name="Grey" />
        </visual>
        <collision>
            <origin rpy="0 0 0" xyz="0 0 0" />
            <geometry>
                <mesh filename="package://iiwa_description/meshes/OnRobot/rg6_body.stl" />
            </geometry>
        </collision>
    </link>
    <!-- joint between link_0 and arm_1 -->
    <joint name="Soft_RG6_joint_1_1" type="revolute">
        <parent link="Soft_RG6_link_0" />
        <child link="Soft_RG6_arm_1" />
        <origin rpy="0 0 0" xyz="0.0 -0.035 0.13" />
        <axis xyz="1 0 0" />
        <limit effort="1" lower="0.95" upper="2.2" velocity="10" />
        <dynamics damping="0.1" />
    </joint>
    <link name="Soft_RG6_arm_1">
        <inertial>
            <origin rpy="0 0 0" xyz="0 0.0 0.0" />
            <mass value="0.01" />
            <inertia ixx="0.001" ixy="0" ixz="0" iyy="0.001" iyz="0" izz="0.001" />
        </inertial>
        <visual>
            <origin rpy="0 0 0" xyz="0 0.0 0.0" />
            <geometry>
                <mesh filename="package://iiwa_description/meshes/OnRobot/rg6_arm.stl" />
            </geometry>
            <material name="Orange" />
        </visual>
        <collision>
            <origin rpy="0 0 0" xyz="0 0.0 0.0" />
            <geometry>
                <mesh filename="package://iiwa_description/meshes/OnRobot/rg6_arm.stl" />
            </geometry>
        </collision>
    </link>
    <!-- joint between arm_1 and finger_1 -->
    <joint name="Soft_RG6_joint_1_2" type="revolute">
        <parent link="Soft_RG6_arm_1" />
        <child link="Soft_RG6_finger_1" />
        <origin rpy="-1.571 3.141592653589793 0" xyz="-0.002 0.065 0.045" />
        <axis xyz="1 0 0" />
        <limit effort="1" lower="-0.62" upper="0.67" velocity="10" />
        <dynamics damping="0.1" />
    </joint>
    <link name="Soft_RG6_finger_1">
        <inertial>
            <origin rpy="0 0 0" xyz="0 0.0 0.0" />
            <mass value="0.01" />
            <inertia ixx="0.001" ixy="0" ixz="0" iyy="0.001" iyz="0" izz="0.001" />
        </inertial>
        <visual>
            <origin rpy="0 0 0" xyz="0 0.0 0.0" />
            <geometry>
                <mesh filename="package://iiwa_description/meshes/OnRobot/rg6_finger.stl" />
            </geometry>
            <material name="Grey" />
        </visual>
        <collision>
            <origin rpy="0 0 0" xyz="0 0.0 0.0" />
            <geometry>
                <mesh filename="package://iiwa_description/meshes/OnRobot/rg6_finger.stl" />
            </geometry>
        </collision>
    </link>
    <!-- joint between link_0 and arm_2 -->
    <joint name="Soft_RG6_joint_2_1" type="revolute">
        <parent link="Soft_RG6_link_0" />
        <child link="Soft_RG6_arm_2" />
        <origin rpy="0 0 -3.14159" xyz="0.0 0.035 0.13" />
        <axis xyz="1 0 0" />
        <limit effort="1" lower="0.95" upper="2.2" velocity="10" />
        <dynamics damping="0.1" />
    </joint>
    <link name="Soft_RG6_arm_2">
        <inertial>
            <origin rpy="0 0 0" xyz="0 0 0.0" />
            <mass value="0.01" />
            <inertia ixx="0.001" ixy="0" ixz="0" iyy="0.001" iyz="0" izz="0.001" />
        </inertial>
        <visual>
            <origin rpy="0 0 0" xyz="0 0 0.0" />
            <geometry>
                <mesh filename="package://iiwa_description/meshes/OnRobot/rg6_arm.stl" />
            </geometry>
            <material name="Orange" />
        </visual>
        <collision>
            <origin rpy="0 0 0" xyz="0 0 0.0" />
            <geometry>
                <mesh filename="package://iiwa_description/meshes/OnRobot/rg6_arm.stl" />
            </geometry>
        </collision>
    </link>
    <!-- joint between arm_2 and finger_2 -->
    <joint name="Soft_RG6_joint_2_2" type="revolute">
        <parent link="Soft_RG6_arm_2" />
        <child link="Soft_RG6_finger_2" />
        <origin rpy="-1.571 3.141592653589793 0" xyz="-0.002 0.065 0.045" />
        <axis xyz="1 0 0" />
        <limit effort="1" lower="-0.62" upper="0.67" velocity="10" />
        <dynamics damping="0.1" />
    </joint>
    <link name="Soft_RG6_finger_2">
        <inertial>
            <origin rpy="0 0 0" xyz="0 0.0 0.0" />
            <mass value="0.01" />
            <inertia ixx="0.001" ixy="0" ixz="0" iyy="0.001" iyz="0" izz="0.001" />
        </inertial>
        <visual>
            <origin rpy="0 0 0" xyz="0 0.0 0.0" />
            <geometry>
                <mesh filename="package://iiwa_description/meshes/OnRobot/rg6_finger.stl" />
            </geometry>
            <material name="Grey" />
        </visual>
        <collision>
            <origin rpy="0 0 0" xyz="0 0.0 0.0" />
            <geometry>
                <mesh filename="package://iiwa_description/meshes/OnRobot/rg6_finger.stl" />
            </geometry>
        </collision>
    </link>
</robot>
